Workbook

Sheet README
A1: NERC supply data - Week 1 Early Warning Dashboard
A3: Purpose | B3: Clean, tidy tables from three NERC reports so a supply-side early warning dashboard can be built and every total traced back to the report.
A4: Sources | B4: NERC 2025 Annual Report; NERC Quarterly Report Q1 2026 (covers 2025/Q4 vs 2026/Q1); NERC Quarterly Report Q2 2026 (covers 2026/Q1 vs 2026/Q2). All three PDFs came from NERC_REPORTS.zip.
A5: Quarters covered | B5: 2025/Q4, 2026/Q1, 2026/Q2. The files contain no quarterly plant or DisCo tables for 2025 Q1-Q3; the Annual Report only has yearly tables and monthly charts for those months.
A6: Sheet: Plants | B6: One row per plant (28 plants). Installed MW, Hydro/Thermal type, and generation per quarter pulled from Plant_Quarter by formula.
A7: Sheet: Plant_Quarter | B7: One row per plant per quarter (84 rows). Blue cells are numbers copied from NERC Table 1 (availability) and Table 2 (generation). Black cells are formulas.
A8: Sheet: DisCo_Quarter | B8: One row per DisCo per quarter (33 rows). From NERC's DisCo Energy Offtake Performance table (Table 4 in the Q1 report, Table 3 in the Q2 report). 'PH' is Port Harcourt as written in the reports.
A9: Sheet: National_Quarter | B9: The report's own national totals for each quarter (blue) next to values calculated here (black).
A10: Sheet: Monthly | B10: Monthly national available capacity and average hourly generation, typed from the chart data labels (Figures A and B in the Q1 and Q2 reports). Labels are rounded to whole numbers.
A11: Sheet: System_Events | B11: System collapses: 2025 (Annual Report Table 25) and 2026 Q1 (Q1 report Table 3). The Q2 report states there were none.
A12: Sheet: Checks | B12: Reconciliation: this workbook's totals against the totals NERC states, with PASS or FAIL. The tolerance cell can be changed.
A13: Units | B13: MW = capacity (available or installed). MWh/h = average hourly energy, numerically the same as average MW. GWh = quarterly total = MWh/h x 24 x days / 1,000. PAF and load percentages are on a 0-100 scale, as in the reports.
A14: Colour code | B14: Blue text = number typed from a report. Black = formula. Green = link to another sheet. Yellow fill = assumption to confirm.
... A19: Verified at build | B19: The 2026/Q1 columns in the Q2 report are identical to the 2026/Q1 columns in the Q1 report for all 28 plants and all 11 DisCos, so no restated figures were found.

Sheet Plants
A1: Plant | B1: Installed capacity (MW) | C1: Type | D1: Generation 2025/Q4 (MWh/h) | E1: Generation 2026/Q1 (MWh/h) | F1: Generation 2026/Q2 (MWh/h) | G1: Change Q1 to Q2 (MWh/h) | H1: Change Q4 to Q1 (MWh/h)
A2: Ihovbor_2 | B2: 461 | C2: Thermal | D2: =SUMIFS(Plant_Quarter!$G$2:$G$85,Plant_Quarter!$A$2:$A$85,$A2,Plant_Quarter!$B$2:$B$85,"2025/Q4") -> 402.46 | E2: =SUMIFS(Plant_Quarter!$G$2:$G$85,Plant_Quarter!$A$2:$A$85,$A2,Plant_Quarter!$B$2:$B$85,"2026/Q1") -> 419.74 | F2: =SUMIFS(Plant_Quarter!$G$2:$G$85,Plant_Quarter!$A$2:$A$85,$A2,Plant_Quarter!$B$2:$B$85,"2026/Q2") -> 419.48 | G2: =F2-E2 -> -0.26 | H2: =E2-D2 -> 17.28
A3: Ikeja_1 | B3: 110 | C3: Thermal | D3: =SUMIFS(Plant_Quarter!$G$2:$G$85,Plant_Quarter!$A$2:$A$85,$A3,Plant_Quarter!$B$2:$B$85,"2025/Q4") -> 90.79 | E3: =SUMIFS(Plant_Quarter!$G$2:$G$85,Plant_Quarter!$A$2:$A$85,$A3,Plant_Quarter!$B$2:$B$85,"2026/Q1") -> 81.46 | F3: =SUMIFS(Plant_Quarter!$G$2:$G$85,Plant_Quarter!$A$2:$A$85,$A3,Plant_Quarter!$B$2:$B$85,"2026/Q2") -> 90.26 | G3: =F3-E3 -> 8.8 | H3: =E3-D3 -> -9.33
A4: Jebba_1 | B4: 578 | C4: Hydro | D4: =SUMIFS(Plant_Quarter!$G$2:$G$85,Plant_Quarter!$A$2:$A$85,$A4,Plant_Quarter!$B$2:$B$85,"2025/Q4") -> 405.91 | E4: =SUMIFS(Plant_Quarter!$G$2:$G$85,Plant_Quarter!$A$2:$A$85,$A4,Plant_Quarter!$B$2:$B$85,"2026/Q1") -> 400.09 | F4: =SUMIFS(Plant_Quarter!$G$2:$G$85,Plant_Quarter!$A$2:$A$85,$A4,Plant_Quarter!$B$2:$B$85,"2026/Q2") -> 363.32 | G4: =F4-E4 -> -36.77 | H4: =E4-D4 -> -5.82
A5: Kainji_1 | B5: 760 | C5: Hydro | D5: =SUMIFS(Plant_Quarter!$G$2:$G$85,Plant_Quarter!$A$2:$A$85,$A5,Plant_Quarter!$B$2:$B$85,"2025/Q4") -> 544.2 | E5: =SUMIFS(Plant_Quarter!$G$2:$G$85,Plant_Quarter!$A$2:$A$85,$A5,Plant_Quarter!$B$2:$B$85,"2026/Q1") -> 528.02 | F5: =SUMIFS(Plant_Quarter!$G$2:$G$85,Plant_Quarter!$A$2:$A$85,$A5,Plant_Quarter!$B$2:$B$85,"2026/Q2") -> 409.44 | G5: =F5-E5 -> -118.58 | H5: =E5-D5 -> -16.18
A6: Okpai_1 | B6: 480 | C6: Thermal | D6: =SUMIFS(Plant_Quarter!$G$2:$G$85,Plant_Quarter!$A$2:$A$85,$A6,Plant_Quarter!$B$2:$B$85,"2025/Q4") -> 246.14 | E6: =SUMIFS(Plant_Quarter!$G$2:$G$85,Plant_Quarter!$A$2:$A$85,$A6,Plant_Quarter!$B$2:$B$85,"2026/Q1") -> 237.28 | F6: =SUMIFS(Plant_Quarter!$G$2:$G$85,Plant_Quarter!$A$2:$A$85,$A6,Plant_Quarter!$B$2:$B$85,"2026/Q2") -> 219.85 | G6: =F6-E6 -> -17.43 | H6: =E6-D6 -> -8.86
A7: Dadin-Kowa_1 | B7: 40 | C7: Hydro | D7: =SUMIFS(Plant_Quarter!$G$2:$G$85,Plant_Quarter!$A$2:$A$85,$A7,Plant_Quarter!$B$2:$B$85,"2025/Q4") -> 33.74 | E7: =SUMIFS(Plant_Quarter!$G$2:$G$85,Plant_Quarter!$A$2:$A$85,$A7,Plant_Quarter!$B$2:$B$85,"2026/Q1") -> 17.05 | F7: =SUMIFS(Plant_Quarter!$G$2:$G$85,Plant_Quarter!$A$2:$A$85,$A7,Plant_Quarter!$B$2:$B$85,"2026/Q2") -> 19.25 | G7: =F7-E7 -> 2.2 | H7: =E7-D7 -> -16.69
A8: Shiroro_1 | B8: 600 | C8: Hydro | D8: =SUMIFS(Plant_Quarter!$G$2:$G$85,Plant_Quarter!$A$2:$A$85,$A8,Plant_Quarter!$B$2:$B$85,"2025/Q4") -> 281.79 | E8: =SUMIFS(Plant_Quarter!$G$2:$G$85,Plant_Quarter!$A$2:$A$85,$A8,Plant_Quarter!$B$2:$B$85,"2026/Q1") -> 269.58 | F8: =SUMIFS(Plant_Quarter!$G$2:$G$85,Plant_Quarter!$A$2:$A$85,$A8,Plant_Quarter!$B$2:$B$85,"2026/Q2") -> 270.61 | G8: =F8-E8 -> 1.03 | H8: =E8-D8 -> -12.21
A9: Zungeru_1 | B9: 700 | C9: Hydro | D9: =SUMIFS(Plant_Quarter!$G$2:$G$85,Plant_Quarter!$A$2:$A$85,$A9,Plant_Quarter!$B$2:$B$85,"2025/Q4") -> 440.17 | E9: =SUMIFS(Plant_Quarter!$G$2:$G$85,Plant_Quarter!$A$2:$A$85,$A9,Plant_Quarter!$B$2:$B$85,"2026/Q1") -> 280.68 | F9: =SUMIFS(Plant_Quarter!$G$2:$G$85,Plant_Quarter!$A$2:$A$85,$A9,Plant_Quarter!$B$2:$B$85,"2026/Q2") -> 314.02 | G9: =F9-E9 -> 33.34 | H9: =E9-D9 -> -159.49
A10: Igbafo_1 | B10: 45 | C10: Thermal | D10: =SUMIFS(Plant_Quarter!$G$2:$G$85,Plant_Quarter!$A$2:$A$85,$A10,Plant_Quarter!$B$2:$B$85,"2025/Q4") -> 17.95 | E10: =SUMIFS(Plant_Quarter!$G$2:$G$85,Plant_Quarter!$A$2:$A$85,$A10,Plant_Quarter!$B$2:$B$85,"2026/Q1") -> 10.29 | F10: =SUMIFS(Plant_Quarter!$G$2:$G$85,Plant_Quarter!$A$2:$A$85,$A10,Plant_Quarter!$B$2:$B$85,"2026/Q2") -> 14.84 | G10: =F10-E10 -> 4.55 | H10: =E10-D10 -> -7.66
A11: Afam_2 | B11: 650 | C11: Thermal | D11: =SUMIFS(Plant_Quarter!$G$2:$G$85,Plant_Quarter!$A$2:$A$85,$A11,Plant_Quarter!$B$2:$B$85,"2025/Q4") -> 135.57 | E11: =SUMIFS(Plant_Quarter!$G$2:$G$85,Plant_Quarter!$A$2:$A$85,$A11,Plant_Quarter!$B$2:$B$85,"2026/Q1") -> 184.29 | F11: =SUMIFS(Plant_Quarter!$G$2:$G$85,Plant_Quarter!$A$2:$A$85,$A11,Plant_Quarter!$B$2:$B$85,"2026/Q2") -> 291.27 | G11: =F11-E11 -> 106.98 | H11: =E11-D11 -> 48.72
A12: Delta_1 | B12: 900 | C12: Thermal | D12: =SUMIFS(Plant_Quarter!$G$2:$G$85,Plant_Quarter!$A$2:$A$85,$A12,Plant_Quarter!$B$2:$B$85,"2025/Q4") -> 306.65 | E12: =SUMIFS(Plant_Quarter!$G$2:$G$85,Plant_Quarter!$A$2:$A$85,$A12,Plant_Quarter!$B$2:$B$85,"2026/Q1") -> 343.44 | F12: =SUMIFS(Plant_Quarter!$G$2:$G$85,Plant_Quarter!$A$2:$A$85,$A12,Plant_Quarter!$B$2:$B$85,"2026/Q2") -> 365.29 | G12: =F12-E12 -> 21.85 | H12: =E12-D12 -> 36.79
A13: Omotosho_1 | B13: 335 | C13: Thermal | D13: =SUMIFS(Plant_Quarter!$G$2:$G$85,Plant_Quarter!$A$2:$A$85,$A13,Plant_Quarter!$B$2:$B$85,"2025/Q4") -> 82 | E13: =SUMIFS(Plant_Quarter!$G$2:$G$85,Plant_Quarter!$A$2:$A$85,$A13,Plant_Quarter!$B$2:$B$85,"2026/Q1") -> 79.78 | F13: =SUMIFS(Plant_Quarter!$G$2:$G$85,Plant_Quarter!$A$2:$A$85,$A13,Plant_Quarter!$B$2:$B$85,"2026/Q2") -> 135.18 | G13: =F13-E13 -> 55.4 | H13: =E13-D13 -> -2.22
... A29: Geregu_1 | B29: 435 | C29: Thermal | D29: =SUMIFS(Plant_Quarter!$G$2:$G$85,Plant_Quarter!$A$2:$A$85,$A29,Plant_Quarter!$B$2:$B$85,"2025/Q4") -> 220.9 | E29: =SUMIFS(Plant_Quarter!$G$2:$G$85,Plant_Quarter!$A$2:$A$85,$A29,Plant_Quarter!$B$2:$B$85,"2026/Q1") -> 82.38 | F29: =SUMIFS(Plant_Quarter!$G$2:$G$85,Plant_Quarter!$A$2:$A$85,$A29,Plant_Quarter!$B$2:$B$85,"2026/Q2") -> 2.11 | G29: =F29-E29 -> -80.27 | H29: =E29-D29 -> -138.52
A30: Total | B30: =SUM(B2:B29) -> 13625 | D30: =SUM(D2:D29) -> 4452.7 | E30: =SUM(E2:E29) -> 4112.73 | F30: =SUM(F2:F29) -> 4022.41 | G30: =SUM(G2:G29) -> -90.32 | H30: =SUM(H2:H29) -> -339.97

Sheet Plant_Quarter
A1: Plant | B1: Quarter | C1: Type | D1: Installed capacity (MW) | E1: Average available capacity (MW) | F1: PAF reported (%) | G1: Average hourly generation (MWh/h) | H1: PAF recalculated (%) | I1: PAF difference (pp) | J1: Generation / Available (%)
A2: Ihovbor_2 | B2: 2025/Q4 | C2: =INDEX(Plants!$C$2:$C$29,MATCH(A2,Plants!$A$2:$A$29,0)) -> Thermal | D2: =INDEX(Plants!$B$2:$B$29,MATCH(A2,Plants!$A$2:$A$29,0)) -> 461 | E2: 441.68 | F2: 95.81 | G2: 402.46 | H2: =E2/D2*100 -> 95.809111 | I2: =H2-F2 -> -0.00088937093 | J2: =IF(E2=0,0,G2/E2*100) -> 91.120268
A3: Ihovbor_2 | B3: 2026/Q1 | C3: =INDEX(Plants!$C$2:$C$29,MATCH(A3,Plants!$A$2:$A$29,0)) -> Thermal | D3: =INDEX(Plants!$B$2:$B$29,MATCH(A3,Plants!$A$2:$A$29,0)) -> 461 | E3: 453.95 | F3: 98.47 | G3: 419.74 | H3: =E3/D3*100 -> 98.470716 | I3: =H3-F3 -> 0.00071583514 | J3: =IF(E3=0,0,G3/E3*100) -> 92.463928
A4: Ihovbor_2 | B4: 2026/Q2 | C4: =INDEX(Plants!$C$2:$C$29,MATCH(A4,Plants!$A$2:$A$29,0)) -> Thermal | D4: =INDEX(Plants!$B$2:$B$29,MATCH(A4,Plants!$A$2:$A$29,0)) -> 461 | E4: 459.4 | F4: 99.65 | G4: 419.48 | H4: =E4/D4*100 -> 99.652928 | I4: =H4-F4 -> 0.0029284165 | J4: =IF(E4=0,0,G4/E4*100) -> 91.310405
A5: Ikeja_1 | B5: 2025/Q4 | C5: =INDEX(Plants!$C$2:$C$29,MATCH(A5,Plants!$A$2:$A$29,0)) -> Thermal | D5: =INDEX(Plants!$B$2:$B$29,MATCH(A5,Plants!$A$2:$A$29,0)) -> 110 | E5: 110 | F5: 100 | G5: 90.79 | H5: =E5/D5*100 -> 100 | I5: =H5-F5 -> 0 | J5: =IF(E5=0,0,G5/E5*100) -> 82.536364
A6: Ikeja_1 | B6: 2026/Q1 | C6: =INDEX(Plants!$C$2:$C$29,MATCH(A6,Plants!$A$2:$A$29,0)) -> Thermal | D6: =INDEX(Plants!$B$2:$B$29,MATCH(A6,Plants!$A$2:$A$29,0)) -> 110 | E6: 107.48 | F6: 97.71 | G6: 81.46 | H6: =E6/D6*100 -> 97.709091 | I6: =H6-F6 -> -0.00090909091 | J6: =IF(E6=0,0,G6/E6*100) -> 75.790845
A7: Ikeja_1 | B7: 2026/Q2 | C7: =INDEX(Plants!$C$2:$C$29,MATCH(A7,Plants!$A$2:$A$29,0)) -> Thermal | D7: =INDEX(Plants!$B$2:$B$29,MATCH(A7,Plants!$A$2:$A$29,0)) -> 110 | E7: 108.97 | F7: 99.06 | G7: 90.26 | H7: =E7/D7*100 -> 99.063636 | I7: =H7-F7 -> 0.0036363636 | J7: =IF(E7=0,0,G7/E7*100) -> 82.830137
A8: Jebba_1 | B8: 2025/Q4 | C8: =INDEX(Plants!$C$2:$C$29,MATCH(A8,Plants!$A$2:$A$29,0)) -> Hydro | D8: =INDEX(Plants!$B$2:$B$29,MATCH(A8,Plants!$A$2:$A$29,0)) -> 578 | E8: 538.42 | F8: 93.15 | G8: 405.91 | H8: =E8/D8*100 -> 93.152249 | I8: =H8-F8 -> 0.0022491349 | J8: =IF(E8=0,0,G8/E8*100) -> 75.389101
A9: Jebba_1 | B9: 2026/Q1 | C9: =INDEX(Plants!$C$2:$C$29,MATCH(A9,Plants!$A$2:$A$29,0)) -> Hydro | D9: =INDEX(Plants!$B$2:$B$29,MATCH(A9,Plants!$A$2:$A$29,0)) -> 578 | E9: 417.78 | F9: 72.28 | G9: 400.09 | H9: =E9/D9*100 -> 72.280277 | I9: =H9-F9 -> 0.00027681661 | J9: =IF(E9=0,0,G9/E9*100) -> 95.765714
A10: Jebba_1 | B10: 2026/Q2 | C10: =INDEX(Plants!$C$2:$C$29,MATCH(A10,Plants!$A$2:$A$29,0)) -> Hydro | D10: =INDEX(Plants!$B$2:$B$29,MATCH(A10,Plants!$A$2:$A$29,0)) -> 578 | E10: 400.5 | F10: 69.29 | G10: 363.32 | H10: =E10/D10*100 -> 69.290657 | I10: =H10-F10 -> 0.00065743945 | J10: =IF(E10=0,0,G10/E10*100) -> 90.716604
A11: Kainji_1 | B11: 2025/Q4 | C11: =INDEX(Plants!$C$2:$C$29,MATCH(A11,Plants!$A$2:$A$29,0)) -> Hydro | D11: =INDEX(Plants!$B$2:$B$29,MATCH(A11,Plants!$A$2:$A$29,0)) -> 760 | E11: 572.7 | F11: 75.36 | G11: 544.2 | H11: =E11/D11*100 -> 75.355263 | I11: =H11-F11 -> -0.0047368421 | J11: =IF(E11=0,0,G11/E11*100) -> 95.023573
A12: Kainji_1 | B12: 2026/Q1 | C12: =INDEX(Plants!$C$2:$C$29,MATCH(A12,Plants!$A$2:$A$29,0)) -> Hydro | D12: =INDEX(Plants!$B$2:$B$29,MATCH(A12,Plants!$A$2:$A$29,0)) -> 760 | E12: 539.37 | F12: 70.97 | G12: 528.02 | H12: =E12/D12*100 -> 70.969737 | I12: =H12-F12 -> -0.00026315789 | J12: =IF(E12=0,0,G12/E12*100) -> 97.895693
A13: Kainji_1 | B13: 2026/Q2 | C13: =INDEX(Plants!$C$2:$C$29,MATCH(A13,Plants!$A$2:$A$29,0)) -> Hydro | D13: =INDEX(Plants!$B$2:$B$29,MATCH(A13,Plants!$A$2:$A$29,0)) -> 760 | E13: 429.25 | F13: 56.48 | G13: 409.44 | H13: =E13/D13*100 -> 56.480263 | I13: =H13-F13 -> 0.00026315789 | J13: =IF(E13=0,0,G13/E13*100) -> 95.384974
... A85: Geregu_1 | B85: 2026/Q2 | C85: =INDEX(Plants!$C$2:$C$29,MATCH(A85,Plants!$A$2:$A$29,0)) -> Thermal | D85: =INDEX(Plants!$B$2:$B$29,MATCH(A85,Plants!$A$2:$A$29,0)) -> 435 | E85: 2.44 | F85: 0.56 | G85: 2.11 | H85: =E85/D85*100 -> 0.56091954 | I85: =H85-F85 -> 0.00091954023 | J85: =IF(E85=0,0,G85/E85*100) -> 86.47541

Sheet DisCo_Quarter
A1: DisCo | B1: Quarter | C1: Energy offtake (MWh/h) | D1: Available PCC (MWh/h) | E1: Offtake performance reported (%) | F1: Offtake performance recalculated (%) | G1: Difference (pp)
A2: Abuja | B2: 2025/Q4 | C2: 576.75 | D2: 605.85 | E2: 95.2 | F2: =C2/D2*100 -> 95.196831 | G2: =F2-E2 -> -0.0031691013
A3: Abuja | B3: 2026/Q1 | C3: 550.78 | D3: 553.01 | E3: 99.6 | F3: =C3/D3*100 -> 99.596752 | G3: =F3-E3 -> -0.0032476809
A4: Abuja | B4: 2026/Q2 | C4: 520.26 | D4: 589.31 | E4: 88.28 | F4: =C4/D4*100 -> 88.282907 | G4: =F4-E4 -> 0.0029071287
A5: Benin | B5: 2025/Q4 | C5: 353.04 | D5: 353.04 | E5: 100 | F5: =C5/D5*100 -> 100 | G5: =F5-E5 -> 0
A6: Benin | B6: 2026/Q1 | C6: 276.96 | D6: 280.82 | E6: 98.62 | F6: =C6/D6*100 -> 98.625454 | G6: =F6-E6 -> 0.0054540275
A7: Benin | B7: 2026/Q2 | C7: 262.99 | D7: 275.48 | E7: 95.46 | F7: =C7/D7*100 -> 95.466096 | G7: =F7-E7 -> 0.0060955423
A8: Eko | B8: 2025/Q4 | C8: 480.78 | D8: 500.72 | E8: 96.02 | F8: =C8/D8*100 -> 96.017734 | G8: =F8-E8 -> -0.0022655376
A9: Eko | B9: 2026/Q1 | C9: 445.26 | D9: 452.73 | E9: 98.35 | F9: =C9/D9*100 -> 98.35001 | G9: =F9-E9 -> 9.9396992e-06
A10: Eko | B10: 2026/Q2 | C10: 430.21 | D10: 456.51 | E10: 94.24 | F10: =C10/D10*100 -> 94.238899 | G10: =F10-E10 -> -0.0011005235
A11: Enugu | B11: 2025/Q4 | C11: 315.06 | D11: 317.02 | E11: 99.38 | F11: =C11/D11*100 -> 99.381742 | G11: =F11-E11 -> 0.0017424768
A12: Enugu | B12: 2026/Q1 | C12: 262.94 | D12: 264.72 | E12: 99.33 | F12: =C12/D12*100 -> 99.327591 | G12: =F12-E12 -> -0.0024085827
A13: Enugu | B13: 2026/Q2 | C13: 248.95 | D13: 260.73 | E13: 95.48 | F13: =C13/D13*100 -> 95.481916 | G13: =F13-E13 -> 0.0019161585
... A34: Yola | B34: 2026/Q2 | C34: 70.7 | D34: 77.3 | E34: 91.47 | F34: =C34/D34*100 -> 91.461837 | G34: =F34-E34 -> -0.0081630013

Sheet National_Quarter
A1: Quarter | B1: Days in quarter | C1: Installed capacity reported (MW) | D1: Avg available capacity reported (MW) | E1: PAF reported (%) | F1: Avg hourly generation reported (MWh/h) | G1: Total generation reported (GWh) | H1: DisCo offtake reported (MWh/h) | I1: DisCo PCC reported (MWh/h) | J1: DisCo offtake reported (GWh) | K1: Total generation calculated (GWh) | L1: Generation minus DisCo offtake (MWh/h) | M1: DisCo offtake as % of generation
A2: 2025/Q4 | B2: 92 | C2: 13625 | D2: 5400.38 | E2: 39.64 | F2: 4452.71 | G2: 9831.58 | H2: 3619.21 | I2: 3926.15 | J2: n/a | K2: =F2*24*B2/1000 -> 9831.5837 | L2: =F2-H2 -> 833.5 | M2: =H2/F2*100 -> 81.281063
A3: 2026/Q1 | B3: 90 | C3: 13625 | D3: 4457.96 | E3: 32.72 | F3: 4112.72 | G3: 8883.47 | H3: 3309.48 | I3: 3408.02 | J3: 7148.47 | K3: =F3*24*B3/1000 -> 8883.4752 | L3: =F3-H3 -> 803.24 | M3: =H3/F3*100 -> 80.469373
A4: 2026/Q2 | B4: 91 | C4: 13625 | D4: 4454.17 | E4: 32.69 | F4: 4022.4 | G4: 8784.93 | H4: 3197.03 | I4: 3398.41 | J4: 6982.32 | K4: =F4*24*B4/1000 -> 8784.9216 | L4: =F4-H4 -> 825.37 | M4: =H4/F4*100 -> 79.480658
A6: Notes
A7: Days: 92, 90 and 91 are the day counts NERC states in its report footnotes. DisCo offtake in GWh was not stated for 2025/Q4 in the Q1 report extract, so it shows n/a.
A8: Column L is the gap between what the plants generated and what the DisCos took at their trading points. The tables do not explain this gap, so treat it as a question to investigate.

Sheet Monthly
A1: Month | B1: Quarter | C1: Avg available capacity (MW) | D1: Avg hourly generation (MWh/h) | E1: Generation / Available (%)
A2: Oct-25 | B2: 2025/Q4 | C2: 5506 | D2: 4290 | E2: =D2/C2*100 -> 77.915002
A3: Nov-25 | B3: 2025/Q4 | C3: 5544 | D3: 4701 | E3: =D3/C3*100 -> 84.794372
A4: Dec-25 | B4: 2025/Q4 | C4: 5151 | D4: 4367 | E4: =D4/C4*100 -> 84.779654
A5: Jan-26 | B5: 2026/Q1 | C5: 4901 | D5: 4421 | E5: =D5/C5*100 -> 90.20608
A6: Feb-26 | B6: 2026/Q1 | C6: 4384 | D6: 4102 | E6: =D6/C6*100 -> 93.567518
A7: Mar-26 | B7: 2026/Q1 | C7: 4089 | D7: 3815 | E7: =D7/C7*100 -> 93.299095
A8: Apr-26 | B8: 2026/Q2 | C8: 4286 | D8: 4048 | E8: =D8/C8*100 -> 94.447037
A9: May-26 | B9: 2026/Q2 | C9: 4587 | D9: 4128 | E9: =D9/C9*100 -> 89.99346
A10: Jun-26 | B10: 2026/Q2 | C10: 4489 | D10: 3892 | E10: =D10/C10*100 -> 86.700824
A12: Source: chart data labels, Figure A and Figure B in the Q1 2026 report (Oct-25 to Mar-26) and the Q2 2026 report (Jan-26 to Jun-26). Labels are rounded to whole numbers, so quarter averages differ slightly from the reported quarterly figures.
A13: Quarter average check (simple average of the three months):
A14: 2025/Q4 | C14: =AVERAGEIFS($C$2:$C$10,$B$2:$B$10,A14) -> 5400.3333 | D14: =AVERAGEIFS($D$2:$D$10,$B$2:$B$10,A14) -> 4452.6667
A15: 2026/Q1 | C15: =AVERAGEIFS($C$2:$C$10,$B$2:$B$10,A15) -> 4458 | D15: =AVERAGEIFS($D$2:$D$10,$B$2:$B$10,A15) -> 4112.6667
A16: 2026/Q2 | C16: =AVERAGEIFS($C$2:$C$10,$B$2:$B$10,A16) -> 4454 | D16: =AVERAGEIFS($D$2:$D$10,$B$2:$B$10,A16) -> 4022.6667

Sheet System_Events
A1: Date | B1: Quarter | C1: Type | D1: Time of collapse (as reported) | E1: Restoration (as reported) | F1: Cause (short summary) | G1: Source
A2: 45910 | B2: 2025/Q3 | C2: Full | D2: 11:20Hrs | E2: 10/09/2025 11:48Hrs | F2: Cause not clearly tied to this event in the PDF layout. Check page 154 of the Annual Report. | G2: Annual Report 2025, Table 25
A3: 46020 | B3: 2025/Q4 | C3: Partial | D3: 14:01Hrs | E3: 29/12/2025 14:30Hrs | F3: Remarks text in the PDF mentions a failed circuit breaker on the Benin-Onitsha 330kV line at Benin station. Confirm on page 154 which event it belongs to. | G3: Annual Report 2025, Table 25
A4: 46045 | B4: 2026/Q1 | C4: Total | D4: 12:40Hrs | E4: not stated | F4: Busbar separation at Sapele transmission station cut the evacuation lines in the Delta corridor, then generation was lost and frequency decayed. | G4: Q1 2026 report, Table 3
A5: 46049 | B5: 2026/Q1 | C5: Partial | D5: 10.48Hrs (as printed) | E5: not stated | F5: Preliminary observation: not enough reactive power to hold voltage margins. | G5: Q1 2026 report, Table 3
A6: none | B6: 2026/Q2 | C6: none | D6: n/a | E6: n/a | F6: The Q2 report states there were no system disturbances on the National Grid. | G6: Q2 2026 report, Summary
A8: Annual Report Table 24 counts collapses per year (2019-2025). 2025: 1 partial and 1 total. The 10/09/2025 event is listed as 'Full' in Table 25 but 'Total' in the Table 24 category.

Sheet Checks
A1: Reconciliation against the totals stated in the reports
A2: Tolerance | B2: 0.02 | C2: Rounding in the reports causes differences up to about 0.01. A bigger gap means a data entry error. Change this cell to test a stricter or looser limit.
A3: Tolerance for 'change' checks | B3: 0.05 | C3: Used for generation-change rows only. Each change sums up to 28 rounded plant values, so rounding can build up. Every individual plant change here is within 0.01 of the printed value.
A4: Check | B4: This workbook | C4: Report states | D4: Difference | E4: Result
A5: Installed capacity, sum of 28 plants (MW) | B5: =Plants!B30 -> 13625 | C5: =National_Quarter!C3 -> 13625 | D5: =ABS(B5-C5) -> 0 | E5: =IF(D5<=$B$2,"PASS","FAIL") -> PASS
A6: 2025/Q4 available capacity, sum of plants (MW) | B6: =SUMIFS(Plant_Quarter!$E$2:$E$85,Plant_Quarter!$B$2:$B$85,"2025/Q4") -> 5400.38 | C6: =National_Quarter!D2 -> 5400.38 | D6: =ABS(B6-C6) -> 0 | E6: =IF(D6<=$B$2,"PASS","FAIL") -> PASS
A7: 2026/Q1 available capacity, sum of plants (MW) | B7: =SUMIFS(Plant_Quarter!$E$2:$E$85,Plant_Quarter!$B$2:$B$85,"2026/Q1") -> 4457.95 | C7: =National_Quarter!D3 -> 4457.96 | D7: =ABS(B7-C7) -> 0.01 | E7: =IF(D7<=$B$2,"PASS","FAIL") -> PASS
A8: 2026/Q2 available capacity, sum of plants (MW) | B8: =SUMIFS(Plant_Quarter!$E$2:$E$85,Plant_Quarter!$B$2:$B$85,"2026/Q2") -> 4454.17 | C8: =National_Quarter!D4 -> 4454.17 | D8: =ABS(B8-C8) -> 0 | E8: =IF(D8<=$B$2,"PASS","FAIL") -> PASS
A9: 2025/Q4 average hourly generation, sum of plants (MWh/h) | B9: =SUMIFS(Plant_Quarter!$G$2:$G$85,Plant_Quarter!$B$2:$B$85,"2025/Q4") -> 4452.7 | C9: =National_Quarter!F2 -> 4452.71 | D9: =ABS(B9-C9) -> 0.01 | E9: =IF(D9<=$B$2,"PASS","FAIL") -> PASS
A10: 2026/Q1 average hourly generation, sum of plants (MWh/h) | B10: =SUMIFS(Plant_Quarter!$G$2:$G$85,Plant_Quarter!$B$2:$B$85,"2026/Q1") -> 4112.73 | C10: =National_Quarter!F3 -> 4112.72 | D10: =ABS(B10-C10) -> 0.01 | E10: =IF(D10<=$B$2,"PASS","FAIL") -> PASS
A11: 2026/Q2 average hourly generation, sum of plants (MWh/h) | B11: =SUMIFS(Plant_Quarter!$G$2:$G$85,Plant_Quarter!$B$2:$B$85,"2026/Q2") -> 4022.41 | C11: =National_Quarter!F4 -> 4022.4 | D11: =ABS(B11-C11) -> 0.01 | E11: =IF(D11<=$B$2,"PASS","FAIL") -> PASS
A12: 2025/Q4 PAF recalculated from totals (%) | B12: =SUMIFS(Plant_Quarter!$E$2:$E$85,Plant_Quarter!$B$2:$B$85,"2025/Q4")/Plants!B30*100 -> 39.635817 | C12: =National_Quarter!E2 -> 39.64 | D12: =ABS(B12-C12) -> 0.0041834862 | E12: =IF(D12<=$B$2,"PASS","FAIL") -> PASS
A13: 2026/Q1 PAF recalculated from totals (%) | B13: =SUMIFS(Plant_Quarter!$E$2:$E$85,Plant_Quarter!$B$2:$B$85,"2026/Q1")/Plants!B30*100 -> 32.718899 | C13: =National_Quarter!E3 -> 32.72 | D13: =ABS(B13-C13) -> 0.0011009174 | E13: =IF(D13<=$B$2,"PASS","FAIL") -> PASS
A14: 2026/Q2 PAF recalculated from totals (%) | B14: =SUMIFS(Plant_Quarter!$E$2:$E$85,Plant_Quarter!$B$2:$B$85,"2026/Q2")/Plants!B30*100 -> 32.691156 | C14: =National_Quarter!E4 -> 32.69 | D14: =ABS(B14-C14) -> 0.0011559633 | E14: =IF(D14<=$B$2,"PASS","FAIL") -> PASS
A15: 2025/Q4 total generation from MWh/h x 24 x days (GWh) | B15: =National_Quarter!K2 -> 9831.5837 | C15: =National_Quarter!G2 -> 9831.58 | D15: =ABS(B15-C15) -> 0.00368 | E15: =IF(D15<=$B$2,"PASS","FAIL") -> PASS
A16: 2026/Q1 total generation from MWh/h x 24 x days (GWh) | B16: =National_Quarter!K3 -> 8883.4752 | C16: =National_Quarter!G3 -> 8883.47 | D16: =ABS(B16-C16) -> 0.0052 | E16: =IF(D16<=$B$2,"PASS","FAIL") -> PASS
A17: 2026/Q2 total generation from MWh/h x 24 x days (GWh) | B17: =National_Quarter!K4 -> 8784.9216 | C17: =National_Quarter!G4 -> 8784.93 | D17: =ABS(B17-C17) -> 0.0084 | E17: =IF(D17<=$B$2,"PASS","FAIL") -> PASS
A18: 2025/Q4 DisCo offtake, sum of 11 DisCos (MWh/h) | B18: =SUMIFS(DisCo_Quarter!$C$2:$C$34,DisCo_Quarter!$B$2:$B$34,"2025/Q4") -> 3619.21 | C18: =National_Quarter!H2 -> 3619.21 | D18: =ABS(B18-C18) -> 0 | E18: =IF(D18<=$B$2,"PASS","FAIL") -> PASS
A19: 2026/Q1 DisCo offtake, sum of 11 DisCos (MWh/h) | B19: =SUMIFS(DisCo_Quarter!$C$2:$C$34,DisCo_Quarter!$B$2:$B$34,"2026/Q1") -> 3309.48 | C19: =National_Quarter!H3 -> 3309.48 | D19: =ABS(B19-C19) -> 0 | E19: =IF(D19<=$B$2,"PASS","FAIL") -> PASS
A20: 2026/Q2 DisCo offtake, sum of 11 DisCos (MWh/h) | B20: =SUMIFS(DisCo_Quarter!$C$2:$C$34,DisCo_Quarter!$B$2:$B$34,"2026/Q2") -> 3197.05 | C20: =National_Quarter!H4 -> 3197.03 | D20: =ABS(B20-C20) -> 0.02 | E20: =IF(D20<=$B$2,"PASS","FAIL") -> PASS
A21: 2025/Q4 DisCo PCC, sum of 11 DisCos (MWh/h) | B21: =SUMIFS(DisCo_Quarter!$D$2:$D$34,DisCo_Quarter!$B$2:$B$34,"2025/Q4") -> 3926.15 | C21: =National_Quarter!I2 -> 3926.15 | D21: =ABS(B21-C21) -> 0 | E21: =IF(D21<=$B$2,"PASS","FAIL") -> PASS
A22: 2026/Q1 DisCo PCC, sum of 11 DisCos (MWh/h) | B22: =SUMIFS(DisCo_Quarter!$D$2:$D$34,DisCo_Quarter!$B$2:$B$34,"2026/Q1") -> 3408.02 | C22: =National_Quarter!I3 -> 3408.02 | D22: =ABS(B22-C22) -> 0 | E22: =IF(D22<=$B$2,"PASS","FAIL") -> PASS
A23: 2026/Q2 DisCo PCC, sum of 11 DisCos (MWh/h) | B23: =SUMIFS(DisCo_Quarter!$D$2:$D$34,DisCo_Quarter!$B$2:$B$34,"2026/Q2") -> 3398.4 | C23: =National_Quarter!I4 -> 3398.41 | D23: =ABS(B23-C23) -> 0.01 | E23: =IF(D23<=$B$2,"PASS","FAIL") -> PASS
A24: 2026/Q1 DisCo offtake in GWh from MWh/h x 24 x days | B24: =National_Quarter!H3*24*National_Quarter!B3/1000 -> 7148.4768 | C24: =National_Quarter!J3 -> 7148.47 | D24: =ABS(B24-C24) -> 0.0068 | E24: =IF(D24<=$B$2,"PASS","FAIL") -> PASS
A25: 2026/Q2 DisCo offtake in GWh from MWh/h x 24 x days | B25: =National_Quarter!H4*24*National_Quarter!B4/1000 -> 6982.3135 | C25: =National_Quarter!J4 -> 6982.32 | D25: =ABS(B25-C25) -> 0.00648 | E25: =IF(D25<=$B$2,"PASS","FAIL") -> PASS
A26: 2025/Q4 row count in Plant_Quarter (expect 28 plants) | B26: =COUNTIFS(Plant_Quarter!$B$2:$B$85,"2025/Q4") -> 28 | C26: 28 | D26: =ABS(B26-C26) -> 0 | E26: =IF(D26<=$B$2,"PASS","FAIL") -> PASS
A27: 2026/Q1 row count in Plant_Quarter (expect 28 plants) | B27: =COUNTIFS(Plant_Quarter!$B$2:$B$85,"2026/Q1") -> 28 | C27: 28 | D27: =ABS(B27-C27) -> 0 | E27: =IF(D27<=$B$2,"PASS","FAIL") -> PASS
A28: 2026/Q2 row count in Plant_Quarter (expect 28 plants) | B28: =COUNTIFS(Plant_Quarter!$B$2:$B$85,"2026/Q2") -> 28 | C28: 28 | D28: =ABS(B28-C28) -> 0 | E28: =IF(D28<=$B$2,"PASS","FAIL") -> PASS
A29: 2025/Q4 row count in DisCo_Quarter (expect 11 DisCos) | B29: =COUNTIFS(DisCo_Quarter!$B$2:$B$34,"2025/Q4") -> 11 | C29: 11 | D29: =ABS(B29-C29) -> 0 | E29: =IF(D29<=$B$2,"PASS","FAIL") -> PASS
A30: 2026/Q1 row count in DisCo_Quarter (expect 11 DisCos) | B30: =COUNTIFS(DisCo_Quarter!$B$2:$B$34,"2026/Q1") -> 11 | C30: 11 | D30: =ABS(B30-C30) -> 0 | E30: =IF(D30<=$B$2,"PASS","FAIL") -> PASS
A31: 2026/Q2 row count in DisCo_Quarter (expect 11 DisCos) | B31: =COUNTIFS(DisCo_Quarter!$B$2:$B$34,"2026/Q2") -> 11 | C31: 11 | D31: =ABS(B31-C31) -> 0 | E31: =IF(D31<=$B$2,"PASS","FAIL") -> PASS
A32: Hydro generation change Q1 to Q2 (MWh/h) | B32: =SUMIFS(Plants!G2:G29,Plants!C2:C29,"Hydro") -> -118.78 | C32: -118.79 | D32: =ABS(B32-C32) -> 0.01 | E32: =IF(D32<=$B$3,"PASS","FAIL") -> PASS
A33: Thermal generation change Q1 to Q2 (MWh/h) | B33: =SUMIFS(Plants!G2:G29,Plants!C2:C29,"Thermal") -> 28.46 | C33: 28.47 | D33: =ABS(B33-C33) -> 0.01 | E33: =IF(D33<=$B$3,"PASS","FAIL") -> PASS
A34: Hydro generation change Q4 to Q1 (MWh/h) | B34: =SUMIFS(Plants!H2:H29,Plants!C2:C29,"Hydro") -> -210.39 | C34: -210.38 | D34: =ABS(B34-C34) -> 0.01 | E34: =IF(D34<=$B$3,"PASS","FAIL") -> PASS
A35: Thermal generation change Q4 to Q1 (MWh/h) | B35: =SUMIFS(Plants!H2:H29,Plants!C2:C29,"Thermal") -> -129.58 | C35: -129.61 | D35: =ABS(B35-C35) -> 0.03 | E35: =IF(D35<=$B$3,"PASS","FAIL") -> PASS
A36: Plants with lower generation, Q1 to Q2 (report: 12) | B36: =COUNTIF(Plants!G2:G29,"<0") -> 12 | C36: 12 | D36: =ABS(B36-C36) -> 0 | E36: =IF(D36<=$B$2,"PASS","FAIL") -> PASS
A37: Plants with higher generation, Q1 to Q2 (report: 16) | B37: =COUNTIF(Plants!G2:G29,">0") -> 16 | C37: 16 | D37: =ABS(B37-C37) -> 0 | E37: =IF(D37<=$B$2,"PASS","FAIL") -> PASS
A38: Total generation change Q1 to Q2 (MWh/h) | B38: =Plants!G30 -> -90.32 | C38: -90.32 | D38: =ABS(B38-C38) -> 0 | E38: =IF(D38<=$B$3,"PASS","FAIL") -> PASS
A39: Total generation change Q4 to Q1 (MWh/h) | B39: =Plants!H30 -> -339.97 | C39: -339.99 | D39: =ABS(B39-C39) -> 0.02 | E39: =IF(D39<=$B$3,"PASS","FAIL") -> PASS
A41: Checks passed | B41: =COUNTIF(E5:E39,"PASS") -> 35
...
